<!doctype html>
<html lang="en-US">
  <head>
    <meta charset="utf-8" />
    <meta name="viewport" content="width=device-width" />
    <title>problems with django_extension&#39;s graph_models?</title>
    
    <link rel="stylesheet" href="/static/simple.css-2.2.1/simple.min.css">
  </head>
  <body>
    <header>
      <nav>
        <a href="/">Home</a>
        <a href="/blog/">Blog</a>
        
        <a href="/blog/tags/">Tags</a>
        <a href="/about/">About</a>
        <a href="/services/">Services</a>
        <a href="/contact/">Contact</a>
      </nav>
      <h1>problems with django_extension&#39;s graph_models?</h1>
      
  <div>Published on 2013-11-15T20:14:01.470801+00:00</div>
  
    <div>
    
      <mark>django</mark> &nbsp;
    
      <mark>django_extensions</mark> &nbsp;
    
      <mark>python</mark> &nbsp;
    
    </div>
  

    </header>
    <main>
    
  <section>
  
<p>I recently ran into an issue when trying to generate an image of my project's models using <a href="https://github.com/django-extensions/django-extensions"><code>django_extension</code></a>'s <code>graph_models</code> command. Unfortunately, googling for the error didn't turn up any solutions, so I'm dumping some info here (just in case!).</p>
<h2>some background</h2>
<p>For the record, I was using django_extensions, version 1.2.5 (the latest release as of this post), and Django 1.4.2 (yeah... it's old)</p>
<p>Running the following command:</p>
<pre><code>$ ./manage.py graph_models my_app &gt; my_models.dot
</code></pre>
<p>Gave me the following error</p>
<pre><code>Traceback (most recent call last):
  File &quot;./manage.py&quot;, line 10, in 
 execute\_from\_command\_line(sys.argv)
 File &quot;/home/vagrant/.virtualenvs/my\_app/local/lib/python2.7/site-packages/django/core/management/\_\_init\_\_.py&quot;, line 443, in execute\_from\_command\_line
 utility.execute()
 File &quot;/home/vagrant/.virtualenvs/my\_app/local/lib/python2.7/site-packages/django/core/management/\_\_init\_\_.py&quot;, line 382, in execute
 self.fetch\_command(subcommand).run\_from\_argv(self.argv)
 File &quot;/home/vagrant/.virtualenvs/my\_app/local/lib/python2.7/site-packages/django/core/management/base.py&quot;, line 196, in run\_from\_argv
 self.execute(\*args, \*\*options.\_\_dict\_\_)
 File &quot;/home/vagrant/.virtualenvs/my\_app/local/lib/python2.7/site-packages/django/core/management/base.py&quot;, line 232, in execute
 output = self.handle(\*args, \*\*options)
 File &quot;/home/vagrant/.virtualenvs/my\_app/local/lib/python2.7/site-packages/django\_extensions/management/commands/graph\_models.py&quot;, line 72, in handle
 dotdata = generate\_dot(args, cli\_options=cli\_options, \*\*options)
 File &quot;/home/vagrant/.virtualenvs/my\_app/local/lib/python2.7/site-packages/django\_extensions/management/modelviz.py&quot;, line 168, in generate\_dot
 if field == pk:
 File &quot;/home/vagrant/.virtualenvs/my\_app/local/lib/python2.7/site-packages/django/db/models/fields/\_\_init\_\_.py&quot;, line 128, in \_\_cmp\_\_
 return cmp(self.creation\_counter, other.creation\_counter)
AttributeError: 'NoneType' object has no attribute 'creation\_counter'
</code></pre>
<h2>The problem?</h2>
<p>I'm not entirely sure, but <a href="https://github.com/django-extensions/django-extensions/issues/402">it seems related to this issue</a>.</p>
<h2>The solution</h2>
<p><em>Rather, the solution that worked for me</em> (YMMV): Uninstall your current version:</p>
<pre><code>pip uninstall django-extensions
</code></pre>
<p>Then install the current development version from github:</p>
<pre><code>pip install -e git+https://github.com/django-extensions/django-extensions.git#egg=django_extensions
</code></pre>
<p>Hope that helps someone else!</p>

  </section>

    </main>
    <footer>
      All content copyright &copy; Brad Montgomery.
    </footer>
  </body>
</html>
